#include <iostream>
#include <vector>
#include <stdexcept>
/*
int main()
{
    std::vector<int> num = { 1,2,3,4,5 }; //index goes from 0 - 4

    std::cout << "Atempt to acces index 5...\n";

    try
    {
        //thisis the risky code
        std::cout << num.at(2) << "\n"; //Tries to access index 5, goes out of bound.
    }
    catch (std::out_of_range ex)
    {
        //If the risky code fails, this happens
        std::cout << "Caught an exception: " << ex.what() << "\n";
    }

    std::cout << "hello\n";
    return 0;
}*/